Traceback (most recent call last):
  File "C:\Users\teunm\anaconda3\envs\jupyterbook\lib\site-packages\jupyter_cache\executors\utils.py", line 58, in single_nb_execution
    executenb(
  File "C:\Users\teunm\anaconda3\envs\jupyterbook\lib\site-packages\nbclient\client.py", line 1314, in execute
    return NotebookClient(nb=nb, resources=resources, km=km, **kwargs).execute()
  File "C:\Users\teunm\anaconda3\envs\jupyterbook\lib\site-packages\jupyter_core\utils\__init__.py", line 165, in wrapped
    return loop.run_until_complete(inner)
  File "C:\Users\teunm\anaconda3\envs\jupyterbook\lib\asyncio\base_events.py", line 649, in run_until_complete
    return future.result()
  File "C:\Users\teunm\anaconda3\envs\jupyterbook\lib\site-packages\nbclient\client.py", line 709, in async_execute
    await self.async_execute_cell(
  File "C:\Users\teunm\anaconda3\envs\jupyterbook\lib\site-packages\nbclient\client.py", line 1062, in async_execute_cell
    await self._check_raise_for_error(cell, cell_index, exec_reply)
  File "C:\Users\teunm\anaconda3\envs\jupyterbook\lib\site-packages\nbclient\client.py", line 918, in _check_raise_for_error
    raise CellExecutionError.from_cell_and_msg(cell, exec_reply_content)
nbclient.exceptions.CellExecutionError: An error occurred while executing the following cell:
------------------
p.index = np.arange(len(p))
con = pd.merge(p,conv_data[['total_vaccinations_per_hundred', 'total_cases', 'new_deaths_smoothed_per_million','date']], on='date')
sns.heatmap(con[['stringency_index','total_vaccinations_per_hundred', 'total_cases', 'new_deaths_smoothed_per_million']].corr(),)
plt.show()
------------------


[1;31m---------------------------------------------------------------------------[0m
[1;31mNameError[0m                                 Traceback (most recent call last)
Cell [1;32mIn[4], line 3[0m
[0;32m      1[0m p[38;5;241m.[39mindex [38;5;241m=[39m np[38;5;241m.[39marange([38;5;28mlen[39m(p))
[0;32m      2[0m con [38;5;241m=[39m pd[38;5;241m.[39mmerge(p,conv_data[[[38;5;124m'[39m[38;5;124mtotal_vaccinations_per_hundred[39m[38;5;124m'[39m, [38;5;124m'[39m[38;5;124mtotal_cases[39m[38;5;124m'[39m, [38;5;124m'[39m[38;5;124mnew_deaths_smoothed_per_million[39m[38;5;124m'[39m,[38;5;124m'[39m[38;5;124mdate[39m[38;5;124m'[39m]], on[38;5;241m=[39m[38;5;124m'[39m[38;5;124mdate[39m[38;5;124m'[39m)
[1;32m----> 3[0m [43msns[49m[38;5;241m.[39mheatmap(con[[[38;5;124m'[39m[38;5;124mstringency_index[39m[38;5;124m'[39m,[38;5;124m'[39m[38;5;124mtotal_vaccinations_per_hundred[39m[38;5;124m'[39m, [38;5;124m'[39m[38;5;124mtotal_cases[39m[38;5;124m'[39m, [38;5;124m'[39m[38;5;124mnew_deaths_smoothed_per_million[39m[38;5;124m'[39m]][38;5;241m.[39mcorr(),)
[0;32m      4[0m plt[38;5;241m.[39mshow()

[1;31mNameError[0m: name 'sns' is not defined

